Workbook
Name Accounts_payable: 'List Data'!$C$61:$F$61
Name Cash___Bank: 'List Data'!$C$24:$F$24
Name Debt: 'List Data'!$C$55:$F$55
Name Equity: 'List Data'!$C$49:$F$49
Name Fixed_Assets: 'List Data'!$C$17:$F$17
Name Inventory: 'List Data'!$C$39:$F$39
Name Loans___advances: 'List Data'!$C$73:$F$73
Name Manufacturing: 'List Data'!$C$4:$C$90
Name Operating_Expenses: 'List Data'!$C$90:$F$90
Name Payroll: 'List Data'!$C$30:$F$30
Name Receivables: 'List Data'!$C$46:$F$46
Name Revenue: 'List Data'!$C$84:$F$84
Name Service: 'List Data'!$E$4:$E$90
Name Trading: 'List Data'!$D$4:$D$90
Name Works_Contract: 'List Data'!$F$4:$F$90

Sheet Pending works on each acc bal
A2: Category | B2: Activity | C2: Status
A3: Cash | B3: SPCB5 - If physical verification of cash cannot be conducted at the balance sheet date, perform surprise verifcation of cash during the course of field audit work and obtain confirmation from the management with respect to cash balance as on the balance sheet date | C3: To be done
A4: Receivables | B4: CARE4 - The sale value is calculated and invoice is generated automatically by the application system. Sale prices are obtained from a master file. | C4: Control testing to be done
A5: Receivables | B5: CADRS6 - Write off of bad debts is done only after taking necessry approval from the senior management after recording the reasons for writing off the debtors as bad. | C5: Control testing to be done
A6: Inventory | B6: CAINV1 - Periodic counts of inventory is performed and reconciled to the stock register / general ledger. | C6: Control testing to be done
A7: Loans and Advances | B7: CALA4 - Advances/loans to staff are made as per the entity's policy for staff advances and loans after taking appropriate approvals and receipts are obtained from the staff where they acknowledge the receipt of the loan/advance | C7: Control testing to be done
A8: Accounts Payable | B8: CACL3 - Management reviews and approves payments before processing. | C8: Control testing to be done
A9: Revenue | B9: CARE2 - Invoices are sequentially numbered by the application system and the sequence of invoices processed is accounted for. | C9: Control testing to be done
A10: Revenue | B10: CARE5 - Access to the sales price master file is restricted to authorised personnel only. | C10: Control testing to be done

Sheet NET of FAP
B2: George Infra Private Limited
B3: Statutory Audit for the year ended 31.03.2020
B6: Control Activities | G6: Expected Man hours
B7: Account Balance | C7: Control Activity | D7: Test of control | E7: WP Reference | F7: Required Resource | G7: Min | H7: Max | I7: Avg | J7: Rate | K7: Cost | L7: Remarks
B8: Cash & Bank | C8: CACB1 - Cash on hand is physically verified and agreed with cash book periodically by the management. | D8: 1) Obtain details of physical verification of fixed assets performed by the entity and check if the periodicity of verification is appropriate | F8: Linson Francis | G8: 1 | H8: 1 | I8: =+AVERAGE(G8,H8) -> 1
B9: Cash & Bank | C9: CACB2 - Bank statements are periodically obtained and bank reconciliation statements are prepared every month and are reviewed and approved by the management | D9: 1) Obtain monthly bank reconciliation statements prepared by the entity and check whether the same are approved by the management | F9: Linson Francis | G9: 1 | H9: 1 | I9: =+AVERAGE(G9,H9) -> 1 | L9: 12 samples among all the bank a/cs spread over 12 months
B10: Cash & Bank | C10: CACB3 - Confirmation of bank balances at the balance sheet date for all accounts are obtained by the entity; the scanned copies of which are made available to the auditors. | D10: 1) Obtain bank confirmation statements | F10: Linson Francis | L10: Covered Under SPCB2
B11: Cash & Bank | C11: CACB4 - Bank Accounts are opened and closed with the approval of the Board of Directors. | D11: 1) Obtain minutes of the BoD meetings | F11: Linson Francis | G11: 0.5 | H11: 0.5 | I11: =+AVERAGE(G11,H11) -> 0.5
B12: Cash & Bank | C12: CACB5 - Cash balance is kept under lock & key so as to ensure there is no embezzlement or misappropriation | D12: 1) Check whether Cash is kept under lock & key and the authority for holding the key | F12: Linson Francis
B13: Payroll | C13: CAPAY2 - Biometric attendance systems installed at the office and factory premises ensure that employee attendance data is correctly captured before processing payroll | D13: 1) Obtain reports from the attendance system for a few samples covering the period under audit and check whether the attendance data is correctly captured for processing payroll | F13: Linson Francis | G13: 10 | H13: 14 | I13: =+AVERAGE(G13,H13) -> 12
B14: Inventory | C14: CAINV1 - Periodic counts of inventory is performed and reconciled to the stock register / general ledger. | D14: 1) Obtain details of physical verification of fixed assets performed by the entity and check if the periodicity of verification is appropriate
B15: Receivables | C15: CADRS6 - Write off of bad debts is done only after taking necessry approval from the senior management after recording the reasons for writing off the debtors as bad. | D15: 1) Obtain management approvals for write off of debts | F15: Linson Francis
B16: Accounts Payable | C16: CACL3 - Management reviews and approves payments before processing. | D16: 1) Obtain a few samples for payments processed during the year and check whether the payment is approved by the appropriate authority and whether there are adequate supportings
B17: Loans & Advances | C17: CALA4 - Advances/loans to staff are made as per the entity's policy for staff advances and loans after taking appropriate approvals and receipts are obtained from the staff where they acknowledge the receipt of the loan/advance | D17: 1) Obtain samples of a few staff loans/advances made during the year and compare the same with the entity's policy to see whether the same has been adherred to
B18: Revenue | C18: CARE2 - Invoices are sequentially numbered by the application system and the sequence of invoices processed is accounted for. | D18: 1) Test the sequential numbering of invoices in the system and see whether the same can be bypassed
B19: Revenue | C19: CARE4 - The sale value is calculated and invoice is generated automatically by the application system. Sale prices are obtained from a master file. | D19: 1) Select sample invoices and ensure that the sale prices and discounts given therein are as per the management approved pricelist and discount chart
B20: Revenue | C20: CARE5 - Access to the sales price master file is restricted to authorised personnel only. | D20: 1) Check who has the authority to alter the price master file in the system and whether the same can be bypassed
B21: Revenue | C21: CARE6 - The discount value shown on the invoice is calculated based on the management approved discount rates. | D21: 1) Obtain the management's discount policy and check in respect of a few samples whether the policy has been adherred to
B22: Operating Expenses | C22: CAEXP1 - Invoices and supporting documents are approved by the management before recording in the general ledger. | D22: 1) Obtain a few sample invoices and check whether the same have been authorised by the appropriate authority before recording the same in the general ledger
B25: Substantive procedures | G25: Expected Man hours
B26: Account Balance | C26: Substantive Procedure | D26: Description of Substantive procedure | E26: WP Reference | F26: Required Resource | G26: Min | H26: Max | I26: Avg | J26: Rate | K26: Cost | L26: Remarks
B27: Fixed Assets | C27: SPFA1 - Ensure that the opening balance of Fixed assets have been correctly carried forward from previous reporting period | D27: 1) Obtain opening trial balance of the financial year and compare the same with the closing audited trial balance of the previous year to ensure that the opening balances have been correctly carried forward | F27: Linson Francis | G27: 1 | H27: 3 | I27: =+AVERAGE(G27,H27) -> 2
B28: Fixed Assets | C28: SPFA2 - Obtain a list of Fixed Asset additions during the period and compare the amounts booked in the ledger with the relevant supporting documents. Ensure that all additions during the year have been correctly booked in the respective ledger accounts. | D28: 1) Obtain supportings for the fixed assets purchased during the year and ensure that the amounts are correctly accounted in the books. Check the classification of the additions made and ensure that all necessary compliances with the statutory framework as well as other legal frameworks are met | F28: Linson Francis | G28: 28 | H28: 40 | I28: =+AVERAGE(G28,H28) -> 34
B29: Fixed Assets | C29: SPFA3 - Obtain the records of the physical verification procedures carried out by the entity during the year. Alternatively, we may choose to visit a few locations on our own and physically verfiy the assets. | D29: 1) Obtain details of physical verification of fixed assets performed by the entity and check if the periodicity of verification is appropriate | F29: Linson Francis | G29: 1 | H29: 1 | I29: =+AVERAGE(G29,H29) -> 1 | L29: Already covered under Control testing
B30: Fixed Assets | C30: SPFA4 - Obtain a list of Asset Disposals during the year and ensure that the related amounts have been correctly removed from the Gross Block as well as Accumulated Depreciation | D30: 1) Scrutinise the fixed asset ledgers as well as the cash and bank books to find out any asset disposals during the year. Ensure that the related amounts upto the date of disposal are removed from gross block and accumulated depreciation | F30: Linson Francis | G30: 6 | H30: 10 | I30: =+AVERAGE(G30,H30) -> 8
B31: Fixed Assets | C31: SPFA5 - Obtain the rates of Deprecation for each category of assets as per the Companies Act as well as the Income Tax act and compute the Depreciation Expense for the year as per Companies Act and income Tax Act. | D31: 1) In respect of asset additions during the year, check whether the classification as per companies act and income tax act are proper. Ensure that the useful lives as well as rates of depeciation as given in the statutes are correctly captured 2) Periodically, review the classification of Fixed assets present in the opening block as well to confirm that the classification made earlier still remains appropriate | F31: Linson Francis | G31: 18 | H31: 24 | I31: =+AVERAGE(G31,H31) -> 21
B32: Fixed Assets | C32: SPFA6 - Review the Repairs and maintanence ledger to ensure that no asset which has to be capitalised has been wrongly expensed off | D32: 1) Scrutinise the repairs and maintenance ledger to identify any expenses that meets capitalisation criteria and therefore needs to be capitalised as fixed asset in the books of account | F32: Linson Francis | G32: 14 | H32: 18 | I32: =+AVERAGE(G32,H32) -> 16
B33: Fixed Assets | C33: SPFA7 - Perform test for impairment of fixed assets by evaluating the conditions for impairment as laid down in the applicable financial reporting framework | D33: 1) Perform impairment testing for fixed assets based on the conditions laid out in the financial reporting framework in the event of any fixed asset becoming obsolete/non usable | F33: Govind P | G33: 1 | H33: 3 | I33: =+AVERAGE(G33,H33) -> 2
B34: Cash & Bank | C34: SPCB1 - Perform physical verification of Cash on Hand at the balance sheet date | D34: 1) Visit the location where cash is physically maintained and physically verifiy the same in the presence of the authorised person from the entity's behalf 2) Note down the number of currencies in each denomination and check the physical cash balance with the balance as per the books of account | L34: Couldn't perform due to COVID lockdown
B35: Cash & Bank | C35: SPCB2 - Obtain bank reconciliation statements from the entity for all accounts (including zero balance accounts) and agree the bank book balance to the general ledger and the pass book balance to the bank statement. Trace the reconciling items to the bank statement for the subsequent period or general ledger as the case may be | D35: 1) Match the bank book balance to the general ledger 2) Match the pass book balance to the bank confirmation/statement 3) Trace the subsequent clearance of the reconciling items to the subsequent bank statement. 4) Where the items are not subsequently cleared, check if the instruments have become stale and if any reversal entry needs to be passed | G35: 10 | H35: 14 | I35: =+AVERAGE(G35,H35) -> 12
B36: Cash & Bank | C36: SPCB3 - Obtain balance confirmations for all bank accounts maintained by the entity. | D36: 1) Obtain balance confirmation statements directly from the bank 2) If direct confirmations are not available, have the entity obtain confirmations and communicate the same to the auditors | L36: Covered Under SPCB2
B37: Cash & Bank | C37: SPCB4 - Obtain minutes of Board of directors meeting conducted for the purpose of opening or closing bank accounts | D37: 1) Obtain minutes of BoD meetings and review the same | L37: Covered Under CACB4
B38: Cash & Bank | C38: SPCB5 - If physical verification of cash cannot be conducted at the balance sheet date, perform surprise verifcation of cash during the course of field audit work and obtain confirmation from the management with respect to cash balance as on the balance sheet date | D38: 1) Perform surprise verification of cash on a random date during field audit and compare the physical balance with the book balance 2) Obtain a confirmation from the entity regarding the physical cash balance as on the balance sheet date | G38: 0.5 | H38: 1.5 | I38: =+AVERAGE(G38,H38) -> 1
B39: Payroll | C39: SPPAY1 - Compare monthly payroll data maintained by the HR department with the amounts booked in the respective ledger accounts. Ensure that the net salary after LOP is booked as expense and statutory deductions are booked in the respective liability accounts | D39: 1) Check the payroll computations for each month after considering the base salary and the LOP days. Ensure that the calculations are correct and the correct amount is poseted in the ledger 2) Check if there are reconciling items between the payroll workings and the ledger balance such as amount paid to contract staff and such others who are not in payroll. Check if the grouping of such amounts as salary is appropriate | G39: 130 | H39: 150 | I39: =78+7+16+39 -> 140 | N39: Linson | O39: 78
B40: Payroll | C40: SPPAY2 - Independantly recalculate statutory deductions such as ESI, PF, EWF and compare with the amounts booked in the ledger. Ensure that there are no material differences. | D40: 1) Recalculate statutory deductions based on the rates as given in the statute and ensure that there are no short deductions or material differences | N40: Robin | O40: 7
B41: Payroll | C41: SPPAY3 - Check incentive computation and esnure that the same is consistent through out the period and appropriately accounted | D41: 1) If incentives are paid to the staff, check the parameters for incentive computation and ensure that the incentive is computed appropriately. 2) Also whether statutory deductions are correctly made wherever applocable | N41: Rahul M (Pkd) | O41: 16
B42: Payroll | C42: SPPAY4 - Check the wages/salary payable balance as at the balance sheet date and obtain employeewise, monthwise breakup of the same to identify if there are any long outstanding balances that are no longer payable | D42: 1) Obtain monthwise employeewise split up of the balance in wages payable ledger 2) Check if there are any amounts which are no longer payable and need to be written back 3) Check subsequent settlement of the salary payable balance
B43: Payroll | C43: SPPAY5 - Check the base data given to the actuary for actuarial valuation and ensure that there are no inconsistencies | D43: 1) Compare the salary given for actuarial valuation with the monthly payroll data 2) Trace other data such as joining date, leave data on a sample basis with the employee personnel files, leave cards or such other records | F43: Linson Francis | G43: 6 | H43: 10 | I43: =+AVERAGE(G43,H43) -> 8
B44: Inventory | C44: SPINV1 - Identify significant locations of inventory including third party locations and perform test counts of stock on the balance sheet date | D44: 1) Enquire with the management regarding significant locations of inventory. Visit such locations during the entity's inventory verification process. Observe the enitity's inventory count process and perform test counts on a sample basis
B45: Inventory | C45: SPINV2 - Incase of inventories owned by the entity but located at third party premises, obtain confirmation from the third parties as to the stock in hand as on the balance sheet date. | D45: 1) Visit 3rd party locations where inventory is kept by the entity and perform test counts. 2) If unable to visit, request confirmations for the inventory held by the 3rd parties
...

Sheet Fixed Assets
B2: Dhathri Ayurkendra Private Limited
B3: Statutory Audit for the year ended 31.03.2018
B5: Account Balance | D5: Fixed Assets
B7: Audit objectives, Risk assessment and Responses to assessed risks
B8: Sl No | C8: Risks Identified | D8: Due to Fraud? | E8: Assertion | F8: Control Activity | G8: Planning to rely on Controls? | H8: Planned Substantive procedures | I8: Description of Substantive procedures
B9: 1 | C9: Risk of understatement of fixed assets because assets acquired by the entity are not recorded. | D9: No | E9: Completeness | F9: 1) Periodic counts of fixed assets are performed and reconciled to the fixed asset register / general ledger. | G9: Yes | H9: FA 2 FA 3 | I9: - Additions Testing - Physical Verification
B10: 2 | C10: Risk of understatement of fixed assets because assets in use and still owned by the entity have been wrongly recorded as disposed. | D10: No | E10: Completeness | G10: Yes | H10: FA 2 FA 3 FA 4 | I10: - Additions Testing - Physical Verification - Asset Deletions
B11: 3 | C11: Risk of understatement of fixed assets because fixed assets purchased have been expensed and not capitalised. | D11: No | E11: Completeness | F11: 1) Periodic counts of fixed assets are performed and reconciled to the fixed asset register. 2) Management reviews and approves the journal voucher along with appropriate supporting documentation before recording asset related transactions in the fixed asset register / general ledger. | G11: Yes | H11: FA 2 FA 6 | I11: - Additions Testing - Repairs & Maint - vouching
B12: 4 | C12: Risk of understatement of fixed assets because assets purchased prior to period end have not been recorded at or before the period end. | D12: No | E12: Completeness | G12: Yes | H12: FA 2 FA 6 | I12: - Additions Testing - Repairs & Maint - vouching
B13: 5 | C13: Risk of understatement of fixed assets because depreciation has been recorded for fictitious assets and / or assets that have been disposed of. | D13: No | E13: Completeness, Existence, Rights and obligations | F13: NO SPECIFIC CONTROL ACTIVITY DEFINED AS DEPRECIATION IS CALCULATED BY THE AUDITORS AT THE TIME OF THE AUDIT | G13: No | H13: FA 3 FA 4 FA 5 | I13: - Physical Verification - Asset Deletions - Depreciation computation
B14: 6 | C14: Risk of overstatement of fixed assets because repairs and maintenance expenses have been incorrectly capitalised as fixed assets. | D14: No | E14: Existence, Rights and obligations | F14: 1) Periodic counts of fixed assets are performed and reconciled to the fixed asset register. 2) Management reviews and approves the journal voucher along with appropriate supporting documentation before recording asset related transactions in the fixed asset register / general ledger. | G14: Yes | H14: FA 2 FA 3 FA 6 | I14: - Additions Testing - Physical Verification - Repairs & Maint - vouching
B15: 7 | C15: Risk of overstatement of fixed assets because assets disposed of have not been recorded in the fixed asset register / general ledger. | D15: No | E15: Existence, Rights and obligations | F15: 1) Periodic counts of fixed assets are performed and reconciled to the fixed asset register / general ledger. | G15: Yes | H15: FA 4 | I15: - Asset Deletions
B16: 8 | C16: Risk of overstatement of fixed assets because assets purchased subsequent to period end have been incorrectly recorded before the period end. | D16: No | E16: Existence, Rights and obligations | F16: 1) Management reviews and approves the journal voucher along with appropriate supporting documentation before recording asset related transactions in the fixed asset register / general ledger. | G16: Yes | H16: FA 2 | I16: - Additions Testing
B17: 9 | C17: Risk of overstatement of fixed assets because obsolete / damaged / unusable assets have not been written down to their recoverable value. | D17: No | E17: Valuation and allocation | F17: 1) Periodic counts of fixed assets are performed and reconciled to the fixed asset register / general ledger. | G17: Yes | H17: FA 4 | I17: - Asset Deletions
B18: 10 | C18: Risk of misstatement of fixed assets because cost, depreciation expense and accumulated depreciation as per general ledger do not agree with the fixed asset register. | D18: No | E18: Valuation and allocation, Existence, Completeness | F18: NO SPECIFIC CONTROL ACTIVITY DEFINED AS DEPRECIATION IS CALCULATED BY THE AUDITORS AT THE TIME OF THE AUDIT | G18: No | H18: FA 1 FA 2 FA 4 FA 5 | I18: - OB Testing - Additions Testing - Asset Deletions - Depreciation computation
B19: 11 | C19: Risk of overstatement of fixed assets because impairment to assets have not been recorded. | D19: No | E19: Valuation and allocation | F19: NO SPECIFIC CONTROL ACTIVITY DEFINED AS IMPAIREMENT TO ASSETS IS CALCULATED BY THE AUDITORS AT THE TIME OF THE AUDIT | G19: No | H19: FA 7 | I19: - Impairment Testing
B20: 12 | C20: Risk of misstatement of fixed assets because the depreciation method and / or depreciation rate adopted are not in compliance with the Companies Act / Indian GAAP / Accounting Policy approved by the Management. | D20: No | E20: Valuation and allocation | F20: NO SPECIFIC CONTROL ACTIVITY DEFINED AS DEPRECIATION IS CALCULATED BY THE AUDITORS AT THE TIME OF THE AUDIT | G20: No | H20: FA 1 FA 2 FA 4 FA 5 | I20: - OB Testing - Additions Testing - Asset Deletions - Depreciation computation
B21: 13 | C21: Risk of misstatement of fixed assets because fixed asset register includes fictitious assets or assets which do not exist. | D21: No | E21: Existence, Rights and obligations | F21: 1) Periodic counts of fixed assets are performed and reconciled to the fixed asset register. 2) Management reviews and approves the journal voucher along with appropriate supporting documentation before recording asset related transactions in the fixed asset register / general ledger. | G21: Yes | H21: FA 1 FA 2 FA 3 FA 4 | I21: - OB Testing - Additions Testing - Physical Verification - Asset Deletions
B22: 14 | C22: Risk of misstatement of fixed assets because asset acquisitions and disposals have not been approved by the Management. | D22: No | E22: Existence, Rights and obligations | F22: 1) Management reviews and approves the journal voucher along with appropriate supporting documentation before recording asset related transactions in the fixed asset register / general ledger. | G22: Yes | H22: FA 2 FA 3 FA 4 | I22: - Additions Testing - Physical Verification - Asset Deletions
B23: 15 | C23: Risk of misstatement of fixed assets because depreciation calculated by the application system is incorrect / invalid. | D23: No | E23: Valuation and allocation | F23: NO SPECIFIC CONTROL ACTIVITY DEFINED AS DEPRECIATION IS CALCULATED BY THE AUDITORS AT THE TIME OF THE AUDIT | G23: No | H23: FA 1 FA 2 FA 4 FA 5 | I23: - OB Testing - Additions Testing - Asset Deletions - Depreciation computation
B25: List of Substantive procedures
B26: Sl No | C26: Descriprion of Substantive Procedure | E26: Assertion Addressed | F26: WP Reference
B27: FA 1 | C27: Ensure that the opening balance of Fixed assets have been correctly carried forward from the previous reporting period | E27: Valuation, Completeness | F27: Refer [Opening Balance Verification workings]
B28: FA 2 | C28: Obtain a list of Fixed Asset additions during the period and compare the amounts booked in the ledger with the relevant supporting documents. Ensure that all additions during the year have been correctly booked in the respective ledger accounts. | E28: Valuation, Completeness, Rights and Obligations | F28: Refer [FA Additions vouching]
B29: FA 3 | C29: Obtain the records of the physical verification procedures carried out by the entity during the year. Alternatively, we may choose to visit a few locations on our own and physically verfiy the assets. | E29: Existence, Rights and Obligations | F29: Physical Verification of Fixed assets done by management
B30: FA 4 | C30: Obtain a list of Asset Disposals during the year and ensure that the related amounts have been correctly removed from the Gross Block as well as Accumulated Depreciation | E30: Valuation, Completeness | F30: There are no Asset disposals during the period under audit
B31: FA 5 | C31: Obtain the rates of Deprecation for each category of assets as per the Companies Act as well as the Income Tax act and compute the Depreciation Expense for the year as per Companies Act and income Tax Act. | E31: Valuation, Completeness | F31: Refer [Depreciation workings as per Companies Act]
F32: Refer [Depreciation workings as per Income Tax Act]
B33: FA 6 | C33: Review the Repairs and maintanence ledger to ensure that no asset which has to be capitalised has been wrongly expensed off | E33: Completeness | F33: Refer [Expense Vouching workings]
B34: FA 7 | C34: During the current period, determine whether any of the following factors are present or whether there are other events or changes in circumstances that indicate the carrying amount of a long-lived asset that the entity expects to hold and use may not be recoverable: (1) A significant decrease in the market price of a long-lived asset. (2) A significant adverse change in the extent or manner in which a long-lived asset is being used or in its physical condition. (3) A significant adverse change in legal factors or in the business climate that could affect the value of a long-lived asset, including an adverse action or assessment by a regulator. (4) An accumulation of costs significantly in excess of the amount originally expected for the acquisition or construction of a long-lived asset. (5) A current-period operating or cash flow loss combined with a history of operating or cash flow losses or a projection or forecast that demonstrates continuing losses associated with the use of a long-lived asset. (6) A current expectation that, more likely than not, a long-lived asset will be sold or otherwise disposed of significantly before the end of its previously estimated useful life. | E34: Valuation and Allocation | F34: There are no factors indicating non recoverability of the carrying amount/impairment of an asset

Sheet NET Summary
D2: Expected Man hours
B3: Material class of transaction | C3: Task | D3: Min | E3: Max | F3: Avg | G3: Rate | H3: Average Cost | J3: Hrs | K3: Man days | L3: Required resource | M3: Man days
B4: Fixed Assets | D4: =SUMIF(#REF!,'NET Summary'!$B4,#REF!) -> #REF! | E4: =SUMIF(#REF!,'NET Summary'!$B4,#REF!) -> #REF! | F4: =SUMIF(#REF!,'NET Summary'!$B4,#REF!) -> #REF! | G4: =SUMIF(#REF!,'NET Summary'!$B4,#REF!) -> #REF! | H4: =SUMIF(#REF!,'NET Summary'!$B4,#REF!) -> #REF! | M4: =F4/8 -> #REF!
C5: FA Workings (including CWIP) | J5: 96 | K5: =SUM(J5/8) -> 12 | L5: Linson Francis
C6: FA Vouching (including CWIP) | J6: 12 | K6: =SUM(J6/8) -> 1.5 | L6: First year article
C7: FA Control testing | J7: 4 | K7: =SUM(J7/8) -> 0.5 | L7: First year article
C8: FA Review | J8: 16 | K8: =SUM(J8/8) -> 2 | L8: Govind P
B9: Debt | D9: =SUMIF(#REF!,'NET Summary'!$B9,#REF!) -> #REF! | E9: =SUMIF(#REF!,'NET Summary'!$B9,#REF!) -> #REF! | F9: =SUMIF(#REF!,'NET Summary'!$B9,#REF!) -> #REF! | G9: =SUMIF(#REF!,'NET Summary'!$B9,#REF!) -> #REF! | H9: =SUMIF(#REF!,'NET Summary'!$B9,#REF!) -> #REF! | M9: =F9/8 -> #REF!
C10: Kuri Loans | J10: 16 | K10: =SUM(J10/8) -> 2 | L10: Shahin Shah
C11: Vehicle Loans | J11: 4 | K11: =SUM(J11/8) -> 0.5 | L11: Dheeraj R
C12: Working Capital Loans | J12: 4 | K12: =SUM(J12/8) -> 0.5 | L12: Dheeraj R
C13: Debt Review | J13: 8 | K13: =SUM(J13/8) -> 1 | L13: Govind P
B14: Statutory Payables | D14: =SUMIF(#REF!,'NET Summary'!$B14,#REF!) -> #REF! | E14: =SUMIF(#REF!,'NET Summary'!$B14,#REF!) -> #REF! | F14: =SUMIF(#REF!,'NET Summary'!$B14,#REF!) -> #REF! | G14: =SUMIF(#REF!,'NET Summary'!$B14,#REF!) -> #REF! | H14: =SUMIF(#REF!,'NET Summary'!$B14,#REF!) -> #REF! | M14: =F14/8 -> #REF!
C15: GST Exporting and formating | J15: =K15*8 -> 72 | K15: 9 | L15: First year article
C16: Input workings | J16: =K16*8 -> 24 | K16: 3 | L16: Dheeraj R
C17: GST Output workings | J17: =K17*8 -> 16 | K17: 2 | L17: Linson Francis
C18: GST Output workings | J18: =K18*8 -> 16 | K18: 2 | L18: First year article
C19: GST Consolidation | J19: =K19*8 -> 40 | K19: 5 | L19: Linson Francis
C20: GST Financial summary | J20: =K20*8 -> 12 | K20: 1.5 | L20: Linson Francis
C21: TDS/TCS | J21: =K21*8 -> 80 | K21: 10 | L21: Grasion George
C22: TDS/TCS Exporting | J22: =K22*8 -> 16 | K22: 2 | L22: Grasion George
C23: Statutory payable review | J23: 24 | K23: 3 | L23: Govind P
C24: Statutory payable review | J24: 24 | K24: 3 | L24: Grasion/ Linson
B25: Cash & Bank | D25: =SUMIF(#REF!,'NET Summary'!$B25,#REF!) -> #REF! | E25: =SUMIF(#REF!,'NET Summary'!$B25,#REF!) -> #REF! | F25: =SUMIF(#REF!,'NET Summary'!$B25,#REF!) -> #REF! | G25: =SUMIF(#REF!,'NET Summary'!$B25,#REF!) -> #REF! | H25: =SUMIF(#REF!,'NET Summary'!$B25,#REF!) -> #REF! | M25: =F25/8 -> #REF!
C26: Bank Reconciliation | J26: 16 | K26: =SUM(J26/8) -> 2 | L26: First year article
C27: Cash & Bank Review | J27: 4 | K27: =SUM(J27/8) -> 0.5 | L27: Govind P
B28: Payroll | D28: =SUMIF(#REF!,'NET Summary'!$B28,#REF!) -> #REF! | E28: =SUMIF(#REF!,'NET Summary'!$B28,#REF!) -> #REF! | F28: =SUMIF(#REF!,'NET Summary'!$B28,#REF!) -> #REF! | G28: =SUMIF(#REF!,'NET Summary'!$B28,#REF!) -> #REF! | H28: =SUMIF(#REF!,'NET Summary'!$B28,#REF!) -> #REF! | M28: =F28/8 -> #REF!
C29: Payroll workings | J29: 40 | K29: =SUM(J29/8) -> 5 | L29: Arun K Baiju
C30: Payroll Review | J30: 8 | K30: =SUM(J30/8) -> 1 | L30: Govind P
B31: Inventory | D31: =SUMIF(#REF!,'NET Summary'!$B31,#REF!) -> #REF! | E31: =SUMIF(#REF!,'NET Summary'!$B31,#REF!) -> #REF! | F31: =SUMIF(#REF!,'NET Summary'!$B31,#REF!) -> #REF! | G31: =SUMIF(#REF!,'NET Summary'!$B31,#REF!) -> #REF! | H31: =SUMIF(#REF!,'NET Summary'!$B31,#REF!) -> #REF! | M31: =F31/8 -> #REF!
C32: Inventory Exporting | J32: =14*8 -> 112 | K32: =SUM(J32/8) -> 14 | L32: Nevil + 1 First year article | O32: =J32/2 -> 56
C33: Inventory - Data bank | J33: =12*8 -> 96 | K33: =SUM(J33/8) -> 12 | L33: Nevil + Linson Francis + Grasion George
C34: Inventory - FIFO | J34: 24 | K34: =SUM(J34/8) -> 3 | L34: Nevil + 1 First year article
C35: Inventory - Opening balance correction | J35: 16 | K35: =SUM(J35/8) -> 2 | L35: Nevil + 1 First year article
C36: Inventory - Review | J36: 16 | K36: =SUM(J36/8) -> 2 | L36: Govind P
C37: Inventory - Review | J37: 32 | K37: =SUM(J37/8) -> 4 | L37: Grasion George + Nevil
C38: Inventory - Others | J38: 24 | K38: =SUM(J38/8) -> 3 | L38: Grasion George + Nevil
B39: Receivables | D39: =SUMIF(#REF!,'NET Summary'!$B39,#REF!) -> #REF! | E39: =SUMIF(#REF!,'NET Summary'!$B39,#REF!) -> #REF! | F39: =SUMIF(#REF!,'NET Summary'!$B39,#REF!) -> #REF! | G39: =SUMIF(#REF!,'NET Summary'!$B39,#REF!) -> #REF! | H39: =SUMIF(#REF!,'NET Summary'!$B39,#REF!) -> #REF! | M39: =F39/8 -> #REF!
C40: Receivables - Accuracy of client workings | J40: =K40*8 -> 8 | K40: 1 | L40: First year article
C41: Receivables - Confirmations | J41: =K41*8 -> 16 | K41: 2 | L41: First year article
...

Sheet ROMM & FAP summary - FS level
B2: ROMM and FAP at Financial statement Level (For details of FS level FAP, refer below; For MCOTABD level FAP, refer ensuing sheets)
B4: WP Reference | C4: Risks Identified | D4: Resulting in FS level risk | E4: Whether Pervasive? | F4: Management Plans to address Risk | G4: Further Audit Procedures Planned / Remarks of Auditor
B5: [2020.01 Understanding the entity] | C5: The relationships with suppliers and customers are generally cordial. Rawmaterial imported is supplied against advances paid to suppliers which is not against any contract and therefore there is risk that the party may not honour the purchase transaction | D5: Yes | E5: Yes | F5: The management relies on the long term association they have had with the supplier and is of the opinion that this risk is not material. Further, advance paid at the time of placing an import order is only 15% of the import value after which the supplier starts manufacturing the required batch. Further the entity's agent who facilitates the import transactions acts as an extended arm of the entity and effectively coordinates the transaction. | G5: SPCL6 - Subsequent transactions testing | H5: GRN, Qlty testing etc
B6: [2020.01 Understanding the entity] | C6: Rule 3 of Companies Accounts Rules becomes applicable from 01-04-2023.However rule 11(g) of Companies (Audit and Auditors)Rules becomes applicable from 01-04-2022. | D6: Yes | E6: Yes | F6: Accounting softwares used by entity namely Tallyprime and SAP having audit trial feature. | G6: Testing General IT controls and Application level controls
B7: [2020.01 Understanding the entity] | C7: Risks arising due to overall market conditions including but not limited to price changes of commodities, governmental policies, pandemics etc | D7: Yes | E7: Yes | F7: While preplanning and following a conservative approach to business may alleviate some of these risks, in respect of certain risks, the management will be able to respond only when such risk arises | G7: FAPFS1 to FAPFS 10 given below
B8: [2020.02 Understanding the internal control] | C8: TCWG may inadvertently encroach on the roles and responsibilities of operational management, also play the role of operational management leading to confusion, overlapping duties, or undermining the authority of senior personnel. This can cause friction within the management team, reducing efficiency and effectiveness in decision-making processes. | D8: Yes | E8: Yes | F8: TCWG has delegated certain operational responsibilities to senior management, empowering them to make decisions within their areas of expertise. This Fosters a culture of trust and accountability, allowing senior personnel to lead effectively while TCWG focuses on strategic governance. | G8: It was explained that the entity is in the process of improvising its operations and accordingly there are structural changes happening. The present involvement of TCWG in operations was warranted since the entity reported losses in the year 2022-23 and the directors took a call to take part more in the operational activities in order to tide over the situation and steady the ship. It was informed that their involvement in the operations will be brought down going forward.
B9: [2020.02 Understanding the internal control] | C9: Absence of a formal documented risk assessment process would mean that risks may not be identified or managed effectively, leading to unforeseen issues that could impact the organization’s performance and stability. | D9: Yes | E9: Yes | F9: Active involvement of TCWG in the management has so far ensured that the entity was not caught in any surprise situations due to business risks that impacted the organisation's performance and stability. Further, as per the provisions of Companies act, a third party internal auditor has been appointed by the entity and the entity is planning to move to a risk based internal audit approach this year the scope of which is being finalised. Iit is expected that a formal documented risk assessment process with risk rankings and matrices will be introduced as part of the same | G9: The entity has the capability and resources to appropriately identify, assess and responds to risks as and when they occur even though such process is not documented or formal. Based on our risk assessment process, we observed that the entity has in place adequate controls to respond to risks at business level, FS level and MCOTABD level. The results of the same are given in the respective working papers FAPFS3 - Monitoring of work FAPFS4 - Unpredictable elements FAPFS5 - Audit procedures to obtain persuasive audit evidence
B10: [2020.02 Understanding the internal control] | C10: Non standard journal entries may be used to misrepresent books of account by artificially overstanding or understanding account balances | D10: Yes | E10: No | F10: There is proper control over passing of non standard journal entries in that such rights are limited to select individuals within the organisation | G10: Non standard journal entries are checked during ledger scrutiny FAPFS7 - Journal entry testing
B11: [2020.02 Understanding the internal control] | C11: Control activities at the entity including Authorisation matrices, segregation etc are not documented. | D11: Yes | E11: Yes | F11: It is ensured that eventhough the activities are not documented, there is an in principle system at the entity to ensure that the same are appropriately being followed. Further, as per the provisions of Companies act, an "external" internal auditor has been appointed by the entity and the entity is planning to move to a risk based internal audit approach this year the scope of which is being finalised. Iit is expected that a formal documented risk assessment process with risk rankings and related control activities will be introduced as part of the same | G11: Based on our risk assessment process, we observed that the entity has in place adequate controls to respond to risks at business level, FS level and MCOTABD level. The results of the same are given in the respective working papers FAPFS1 - Engagement team selection FAPFS2 - Firm's QC policy FAPFS3 - Monitoring of work FAPFS4 - Unpredictable elements FAPFS5 - Audit procedures to obtain persuasive audit evidence FAPFS6 - Results of audit procedures from prior years
B12: [2020.01 Understanding the entity] | C12: Risk that all events occurring between the date of the financial statements and the date of the auditor’s report that require adjustment of, or disclosure in, the financial statements are not identified | D12: Yes | E12: Yes | F12: The management prepares monthly financial results for discussing with TCWG. Significant transactions occuring after the balance sheet date are therefore appropriately captured | G12: FAPFS8 - Reviewing subsequent period MIS reports and financial statements FAPFS9 - Reviewing minutes of meeting of BoD Perform inquiries with the management and TCWG on occurrence of significant subsequent events.
B13: [2020.01 Understanding the entity] | C13: Risk that significant related party relationships and transactions are not identified, accounted and appropriately disclosed in the financial statements | D13: Yes | E13: Yes | F13: Related party registers and register of contracts are maintained and related party transactions are entered only after details of the related party are entered in such registers | G13: FAPFS10 - Management representations, statutory registers
B18: Overall responses to assessed risks of misstatement at financial statement level
B19: FAP Code | C19: Description of procedure | G19: Reference
B20: FAPFS1 | C20: The audit engagement team was finalised considering the experience and skill sets of the team members. Staff with prior experience in handling audits of the same entity are selected. The significant audit areas are assigned to team members considering their relative experience and special skills | G20: Engagement Team
B21: FAPFS2 | C21: Meetings are conducted during various stages of the audit process. At the time of commencement of audit, the engagement partner/qualified member explains to the entire team the need to maintain professional skepticism and adherance to ethical requirements throughout the audit. The firm's quality control manual is explained to the team members so that they have an overall idea about the responsibilities towards quality control in an engagement. The significant audit areas are also communicated to the members where more focus and attention of the team is required. | G21: Meeting Minutes
B22: FAPFS3 | C22: The progress of the audit work is closely and periodically monitored by the engagement partner/qualified member so that queries and roadblocks that the engagement team may face while performing the audit engagement are addressed on an immediate basis | G22: Refer Monitoring MoM
B23: FAPFS4 | C23: Unpredictable elements are included as part of the audit procedures such as surprise verification of cash, inventory etc. Additional audit procedures are performed in respect of risks identified as significant risks. | G23: Refer respective Manual WPs
B24: FAPFS5 | C24: The audit procedures are performed at the period end rather than at an interim date. Audit procedures to obtain more extensive and persuasive audit evidence are performed by the auditor in respect of those areas which in the auditor's professional judgement are considered as significant audit areas | G24: 4000-Audit Execution
B25: FAPFS6 | C25: The entity has an effective control environment as per the auditor's evaluation. From prior experiences with the entity, it has been noted that there are sound systems and controls in place at the entity and the management as well as TCWG attach a lot of importance to maintain an effective control environment. Further, the auditor obtained details of control activities in place at the entity. These were reviewed by the auditor and reliance was placed on some of these control activities. The control activities relied upon by the auditor were tested during the audits for the FYs 2022-23 and 2023-24. Where the controls continue to be relevant and no major changes have occured, such a control need to be tested only once in every 3 audits. However, during the year 2024-25 it was ensured that all control activities on which the auditor chooses to rely upon were tested | G25: FAP - Test of controls
G26: FAP - MCOTABD
B27: FAPFS7 | C27: Siginificant and unusual entries (specifically journal entries) made in the books of account are checked as part of ledger scrutiny to seen if they are genuine entries
B28: FAPFS8 | C28: Obtain MIS reports and financial statements prepared for the subsequent period by the management. Check if there are any significant transactions reported therein after the balancesheet date but before the date of auditor's report which require adjustment or disclosure in the financial statements | G28: SA 560 - Subsequent events
B29: FAPFS9 | C29: Obtain minutes of meeting by the board of directors and check if there are any significant events, decisions or transactions reported therein after the balancesheet date but before the date of auditor's report which require adjustment or disclosure in the financial statements
B30: FAPFS10 | C30: Obtain management representations regarding the list of related parties of the company. Identify related party transactions from the books of account and ensure that the same are appropriately disclosed in the financial statements. Obtain register of contracts maintained by the company and check the correctness of related party relationships and transactions recorded therein | G30: 3000 - Communications

Sheet Sheet1
B2: Account Balance | C2: Risks Identified | D2: Assertions addressed | I2: No of assertions addressed | J2: Assertions addressed
B3: Fixed Assets | C3: RSKFA1 - Risk of understatement of fixed assets because assets acquired by the entity are not recorded. | D3: P&D | E3: C | F3: V | I3: 5 | J3: E | K3: R | L3: C | M3: V | N3: A | Q3: =D3&$C3 -> P&DRSKFA1 - Risk of understatement of fixed assets because assets acquired by the entity are not recorded. | R3: =E3&$C$3 -> CRSKFA1 - Risk of understatement of fixed assets because assets acquired by the entity are not recorded. | S3: =F3&$C$3 -> VRSKFA1 - Risk of understatement of fixed assets because assets acquired by the entity are not recorded.
B4: Fixed Assets | C4: RSKFA2 - Risk of understatement of fixed assets because assets in use and still owned by the entity have been wrongly recorded as disposed. | D4: E | E4: R | F4: C | G4: V | Q4: =D4&$C4 -> ERSKFA2 - Risk of understatement of fixed assets because assets in use and still owned by the entity have been wrongly recorded as disposed. | R4: =E4&$C4 -> RRSKFA2 - Risk of understatement of fixed assets because assets in use and still owned by the entity have been wrongly recorded as disposed. | S4: =F4&$C4 -> CRSKFA2 - Risk of understatement of fixed assets because assets in use and still owned by the entity have been wrongly recorded as disposed. | T4: =G4&$C4 -> VRSKFA2 - Risk of understatement of fixed assets because assets in use and still owned by the entity have been wrongly recorded as disposed.
B5: Fixed Assets | C5: RSKFA3 - Risk of understatement of fixed assets because fixed assets purchased have been expensed and not capitalised. | D5: E | E5: R | F5: V | G5: A | Q5: =D5&$C5 -> ERSKFA3 - Risk of understatement of fixed assets because fixed assets purchased have been expensed and not capitalised. | R5: =E5&$C5 -> RRSKFA3 - Risk of understatement of fixed assets because fixed assets purchased have been expensed and not capitalised. | S5: =F5&$C5 -> VRSKFA3 - Risk of understatement of fixed assets because fixed assets purchased have been expensed and not capitalised. | T5: =G5&$C5 -> ARSKFA3 - Risk of understatement of fixed assets because fixed assets purchased have been expensed and not capitalised.
B6: Fixed Assets | C6: RSKFA4 - Risk of overstatement of fixed assets because repairs and maintenance expenses have been incorrectly capitalised as fixed assets. | D6: E | E6: R | F6: V | G6: A | Q6: =D6&$C6 -> ERSKFA4 - Risk of overstatement of fixed assets because repairs and maintenance expenses have been incorrectly capitalised as fixed assets. | R6: =E6&$C6 -> RRSKFA4 - Risk of overstatement of fixed assets because repairs and maintenance expenses have been incorrectly capitalised as fixed assets. | S6: =F6&$C6 -> VRSKFA4 - Risk of overstatement of fixed assets because repairs and maintenance expenses have been incorrectly capitalised as fixed assets. | T6: =G6&$C6 -> ARSKFA4 - Risk of overstatement of fixed assets because repairs and maintenance expenses have been incorrectly capitalised as fixed assets.
B7: Fixed Assets | C7: RSKFA5 - Risk of overstatement of fixed assets because assets disposed of have not been recorded in the fixed asset register / general ledger. | D7: E | E7: R | Q7: =D7&$C7 -> ERSKFA5 - Risk of overstatement of fixed assets because assets disposed of have not been recorded in the fixed asset register / general ledger. | R7: =E7&$C7 -> RRSKFA5 - Risk of overstatement of fixed assets because assets disposed of have not been recorded in the fixed asset register / general ledger.
B8: Fixed Assets | C8: RSKFA6 - Risk of misstatement of fixed assets because initial measurement, subsequent measurement and impairment testing of fixed assets have not been done in the manner specified in the financial reporting framework | D8: E | E8: R | F8: V | G8: A | Q8: =D8&$C8 -> ERSKFA6 - Risk of misstatement of fixed assets because initial measurement, subsequent measurement and impairment testing of fixed assets have not been done in the manner specified in the financial reporting framework | R8: =E8&$C8 -> RRSKFA6 - Risk of misstatement of fixed assets because initial measurement, subsequent measurement and impairment testing of fixed assets have not been done in the manner specified in the financial reporting framework | S8: =F8&$C8 -> VRSKFA6 - Risk of misstatement of fixed assets because initial measurement, subsequent measurement and impairment testing of fixed assets have not been done in the manner specified in the financial reporting framework | T8: =G8&$C8 -> ARSKFA6 - Risk of misstatement of fixed assets because initial measurement, subsequent measurement and impairment testing of fixed assets have not been done in the manner specified in the financial reporting framework
B9: Fixed Assets | C9: RSKFA7 - Risk of misstatement of fixed assets because the depreciation method and / or depreciation rate adopted are not in compliance with the applicable statutes | D9: V | E9: A | Q9: =D9&$C9 -> VRSKFA7 - Risk of misstatement of fixed assets because the depreciation method and / or depreciation rate adopted are not in compliance with the applicable statutes | R9: =E9&$C9 -> ARSKFA7 - Risk of misstatement of fixed assets because the depreciation method and / or depreciation rate adopted are not in compliance with the applicable statutes
B11: Cash & Bank | C11: RSKCB1 - Risk of overstatement of Cash balance (Eg: non-existent cash receipts have been recorded, cash payments omited to be recorded etc.) | D11: E | E11: R | F11: V | I11: 4 | J11: E | K11: R | L11: C | M11: V | Q11: =D11&$C11 -> ERSKCB1 - Risk of overstatement of Cash balance (Eg: non-existent cash receipts have been recorded, cash payments omited to be recorded etc.) | R11: =E11&$C11 -> RRSKCB1 - Risk of overstatement of Cash balance (Eg: non-existent cash receipts have been recorded, cash payments omited to be recorded etc.) | S11: =F11&$C11 -> VRSKCB1 - Risk of overstatement of Cash balance (Eg: non-existent cash receipts have been recorded, cash payments omited to be recorded etc.)
B12: Cash & Bank | C12: RSKCB2 - Risk of understatement of Cash balance (Eg: non-existent cash payments have been recorded, cash receipts omited to be recorded etc.) | D12: E | E12: R | F12: V | Q12: =D12&$C12 -> ERSKCB2 - Risk of understatement of Cash balance (Eg: non-existent cash payments have been recorded, cash receipts omited to be recorded etc.) | R12: =E12&$C12 -> RRSKCB2 - Risk of understatement of Cash balance (Eg: non-existent cash payments have been recorded, cash receipts omited to be recorded etc.) | S12: =F12&$C12 -> VRSKCB2 - Risk of understatement of Cash balance (Eg: non-existent cash payments have been recorded, cash receipts omited to be recorded etc.)
B13: Cash & Bank | C13: RSKCB3 - Risk of misstatement of Cash because cash on hand has been misappropriated / stolen. | D13: E | E13: R | Q13: =D13&$C13 -> ERSKCB3 - Risk of misstatement of Cash because cash on hand has been misappropriated / stolen. | R13: =E13&$C13 -> RRSKCB3 - Risk of misstatement of Cash because cash on hand has been misappropriated / stolen.
B14: Cash & Bank | C14: RSKCB4 - Risk of overstatement of bank balance (Eg: non-existent bank receipts have been recorded, bank payments or charges omitted to be recorded etc) | D14: E | E14: R | F14: C | G14: V | Q14: =D14&$C14 -> ERSKCB4 - Risk of overstatement of bank balance (Eg: non-existent bank receipts have been recorded, bank payments or charges omitted to be recorded etc) | R14: =E14&$C14 -> RRSKCB4 - Risk of overstatement of bank balance (Eg: non-existent bank receipts have been recorded, bank payments or charges omitted to be recorded etc) | S14: =F14&$C14 -> C RSKCB4 - Risk of overstatement of bank balance (Eg: non-existent bank receipts have been recorded, bank payments or charges omitted to be recorded etc) | T14: =G14&$C14 -> VRSKCB4 - Risk of overstatement of bank balance (Eg: non-existent bank receipts have been recorded, bank payments or charges omitted to be recorded etc)
B15: Cash & Bank | C15: RSKCB5 - Risk of understatement of bank balance (Eg: non-existent bank payments recorded, bank receipts omitted to be recorded etc) | D15: E | E15: R | F15: C | G15: V | Q15: =D15&$C15 -> ERSKCB5 - Risk of understatement of bank balance (Eg: non-existent bank payments recorded, bank receipts omitted to be recorded etc) | R15: =E15&$C15 -> RRSKCB5 - Risk of understatement of bank balance (Eg: non-existent bank payments recorded, bank receipts omitted to be recorded etc) | S15: =F15&$C15 -> CRSKCB5 - Risk of understatement of bank balance (Eg: non-existent bank payments recorded, bank receipts omitted to be recorded etc) | T15: =G15&$C15 -> VRSKCB5 - Risk of understatement of bank balance (Eg: non-existent bank payments recorded, bank receipts omitted to be recorded etc)
B16: Cash & Bank | C16: RSKCB6 - Risk of understatement of Bank because interest accrued in the bank accounts have not been recorded by the entity. | D16: R | E16: C | F16: V | Q16: =D16&$C16 -> RRSKCB6 - Risk of understatement of Bank because interest accrued in the bank accounts have not been recorded by the entity. | R16: =E16&$C16 -> CRSKCB6 - Risk of understatement of Bank because interest accrued in the bank accounts have not been recorded by the entity. | S16: =F16&$C16 -> VRSKCB6 - Risk of understatement of Bank because interest accrued in the bank accounts have not been recorded by the entity.
B18: Payroll | C18: RSKPAY1 - Risk of misstatement of payroll expense due to recording of incorrect amount as payroll cost (i.e., due to updation of wrong salary cost in the payroll master file). | D18: O | E18: C | F18: A | G18: CO | I18: 6 | J18: O | K18: CL | L18: C | M18: A | N18: CO | O18: PD | Q18: =D18&$C18 -> ORSKPAY1 - Risk of misstatement of payroll expense due to recording of incorrect amount as payroll cost (i.e., due to updation of wrong salary cost in the payroll master file). | R18: =E18&$C18 -> CRSKPAY1 - Risk of misstatement of payroll expense due to recording of incorrect amount as payroll cost (i.e., due to updation of wrong salary cost in the payroll master file). | S18: =F18&$C18 -> ARSKPAY1 - Risk of misstatement of payroll expense due to recording of incorrect amount as payroll cost (i.e., due to updation of wrong salary cost in the payroll master file). | T18: =G18&$C18 -> CORSKPAY1 - Risk of misstatement of payroll expense due to recording of incorrect amount as payroll cost (i.e., due to updation of wrong salary cost in the payroll master file).
B19: Payroll | C19: RSKPAY2 - Risk of misstatement of payroll expense due to recording of payroll cost in the wrong period. | D19: A | E19: CO | Q19: =D19&$C19 -> ARSKPAY2 - Risk of misstatement of payroll expense due to recording of payroll cost in the wrong period. | R19: =E19&$C19 -> CORSKPAY2 - Risk of misstatement of payroll expense due to recording of payroll cost in the wrong period.
B20: Payroll | C20: RSKPAY3 - Risk of understatement of payroll cost because the withheld taxes and other deductions are not recorded (i.e., payroll cost is recorded for net payroll and not gross payroll). | D20: C | E20: A | Q20: =D20&$C20 -> CRSKPAY3 - Risk of understatement of payroll cost because the withheld taxes and other deductions are not recorded (i.e., payroll cost is recorded for net payroll and not gross payroll). | R20: =E20&$C20 -> ARSKPAY3 - Risk of understatement of payroll cost because the withheld taxes and other deductions are not recorded (i.e., payroll cost is recorded for net payroll and not gross payroll).
B21: Payroll | C21: RSKPAY4 - Risk of misstatement of Provident Fund and ESI expense recorded because the statutory rate of contribution applied is incorrect or contribution has not been calculated for all employees due to processing errors. | D21: C | E21: A | Q21: =D21&$C21 -> CRSKPAY4 - Risk of misstatement of Provident Fund and ESI expense recorded because the statutory rate of contribution applied is incorrect or contribution has not been calculated for all employees due to processing errors. | R21: =E21&$C21 -> ARSKPAY4 - Risk of misstatement of Provident Fund and ESI expense recorded because the statutory rate of contribution applied is incorrect or contribution has not been calculated for all employees due to processing errors.
B22: Payroll | C22: RSKPAY5 - Risk of misstatement of leave salary expense and accrual because the leave, salary and other relevant data provided for actuarial valuation is incorrect and disclosures required as per the financial reporting framework are not given | D22: C | E22: A | F22: CL | Q22: =D22&$C22 -> CRSKPAY5 - Risk of misstatement of leave salary expense and accrual because the leave, salary and other relevant data provided for actuarial valuation is incorrect and disclosures required as per the financial reporting framework are not given | R22: =E22&$C22 -> ARSKPAY5 - Risk of misstatement of leave salary expense and accrual because the leave, salary and other relevant data provided for actuarial valuation is incorrect and disclosures required as per the financial reporting framework are not given | S22: =F22&$C22 -> CLRSKPAY5 - Risk of misstatement of leave salary expense and accrual because the leave, salary and other relevant data provided for actuarial valuation is incorrect and disclosures required as per the financial reporting framework are not given
B23: Payroll | C23: RSKPAY6 - Risk that employee costs are not recorded in the correct ledgers according to their nature (direct wages, indirect costs, staff welfare etc) which could impact calculation of production overhead rates and consquently inventory valuation. | D23: CL | E23: P&D | Q23: =D23&$C23 -> CLRSKPAY6 - Risk that employee costs are not recorded in the correct ledgers according to their nature (direct wages, indirect costs, staff welfare etc) which could impact calculation of production overhead rates and consquently inventory valuation. | R23: =E23&$C23 -> P&DRSKPAY6 - Risk that employee costs are not recorded in the correct ledgers according to their nature (direct wages, indirect costs, staff welfare etc) which could impact calculation of production overhead rates and consquently inventory valuation.
B25: Inventory | C25: RSKINV1 - Risk of understatement of Inventory because inventory on hand and inventory received from suppliers are not included in inventory records. | D25: E | E25: R | F25: C | G25: V | I25: 6 | J25: E | K25: R | L25: C | M25: V | N25: A | O25: P&D | Q25: =D25&$C25 -> ERSKINV1 - Risk of understatement of Inventory because inventory on hand and inventory received from suppliers are not included in inventory records. | R25: =E25&$C25 -> RRSKINV1 - Risk of understatement of Inventory because inventory on hand and inventory received from suppliers are not included in inventory records. | S25: =F25&$C25 -> CRSKINV1 - Risk of understatement of Inventory because inventory on hand and inventory received from suppliers are not included in inventory records. | T25: =G25&$C25 -> VRSKINV1 - Risk of understatement of Inventory because inventory on hand and inventory received from suppliers are not included in inventory records.
B26: Inventory | C26: RSKINV2 - Risk of overstatement of Inventory because inventory records include inventory that has been sold to customers / consumed. | D26: E | E26: R | F26: C | Q26: =D26&$C26 -> ERSKINV2 - Risk of overstatement of Inventory because inventory records include inventory that has been sold to customers / consumed. | R26: =E26&$C26 -> RRSKINV2 - Risk of overstatement of Inventory because inventory records include inventory that has been sold to customers / consumed. | S26: =F26&$C26 -> CRSKINV2 - Risk of overstatement of Inventory because inventory records include inventory that has been sold to customers / consumed.
